Workbook

Sheet Read me
A1: Read me
A3: Two warnings first
A4: Do not set QUMO_DORMANT_ERASE_AFTER_DAYS without reading item 4 of docs/popia.md. The dormancy sweep would erase unspent balances along with the dormant account, and POPIA section 14 pulls against CPA sections 35 and 63 on exactly that point. Item 3.2.
A5: A cloud slip reader makes that vendor a POPIA operator and, if it is offshore, a section 72 transborder flow the shopper notice has to disclose. A reader running in our own process avoids all of it. Item 3.3.
A7: What the tabs are
A8: Open items: one row per item, grouped by section, filterable. Edit Status, Target date and Your notes. Leave ID, Section, Item, Owner, Gates a pilot, Warning, Detail and Reference alone, because they are generated and will be overwritten if this file is rebuilt.
A9: Summary: counts, all by formula off the Open items tab. Change a status there and these move.
A10: Self-serve signup: the three pieces, since the decision is being weighed.
A12: Owners
A13: Allan: yours. Lawyer: needs a lawyer and therefore calendar time. Claude: can be built. A pair means both are needed.
A15: Statuses
A16: Not started, In progress, Waiting on someone, Blocked, Done, Parked. Done and Parked both drop out of the by-owner counts on the Summary tab; Blocked does not, on purpose.
... A22: docs/popia.md, docs/terms-brief.md, docs/legal-draft-for-review.md, docs/consent-copy.md, docs/photo-capture.md, docs/competitive-position.md, docs/vaultbook-review.md, docs/brand-context.md, docs/website-brief.md, docs/deploying.md, lib/consumer/consent.ts

Sheet Open items
A1: Qumo: what is still open
A2: Status, Target date and Your notes are yours to edit. Everything else is generated from docs/open-items.md, so a change there is not a change here. Two red warnings below are load-bearing: read them before acting on items 3.2 and 3.3.
A4: ID | B4: Section | C4: Item | D4: Owner | E4: Gates a pilot | F4: Status | G4: Target date | H4: Warning | I4: Detail | J4: Reference | K4: Your notes
A5: 1.1 | B5: 1. Gates a pilot with real shoppers | C5: Confirm or overturn the responsible-party split | D5: Lawyer | E5: Yes | F5: Not started | I5: The code implements "both, for different purposes" and the shopper notice now says so. If a lawyer lands elsewhere, the notice changes and every brand needs its own consent captured at join, which is a product change rather than a wording one. | J5: docs/popia.md
A6: 1.2 | B6: 1. Gates a pilot with real shoppers | C6: Get the shopper copy reviewed | D6: Lawyer | E6: Yes | F6: Not started | I6: Written and ready to send, with the three points worth reading first and its queries marked. docs/consent-copy.md is the generated current copy beside it. | J6: docs/legal-draft-for-review.md
A7: 1.3 | B7: 1. Gates a pilot with real shoppers | C7: Appoint an Information Officer and register with the Information Regulator | D7: Allan | E7: Yes | F7: Not started | I7: Only if the responsible-party split is confirmed. Calendar time, not build time.
A8: 1.4 | B8: 1. Gates a pilot with real shoppers | C8: Give a shopper a way to reach Qumo | D8: Claude | E8: Yes | F8: Not started | I8: There is none. Every route runs through whichever brand they scanned. Tolerable for an operator, not for a responsible party.
A9: 1.5 | B9: 1. Gates a pilot with real shoppers | C9: Write down the breach process (POPIA section 22) | D9: Allan + lawyer | E9: Yes | F9: Not started | I9: Who decides, how fast, who signs the notification.
A10: 1.6 | B10: 1. Gates a pilot with real shoppers | C10: Draft the brand agreement | D10: Lawyer | E10: Yes | F10: Not started | I10: Including the operator clause and the section 21 security obligation.
A11: 2.1 | B11: 2. Legal questions already written down | C11: CPA section 35: loyalty credits as a medium of exchange | D11: Lawyer | E11: No | F11: Not started | I11: Loyalty credits are a legal medium of exchange "despite any provision in any law, agreement or notice to the contrary". The terms currently say balances are not. Also: issuing value while redemption is closed, against the prohibition on offering a programme without the intention of providing the award. | J11: docs/terms-brief.md
A12: 2.2 | B12: 2. Legal questions already written down | C12: CPA section 63: the three-year life of a prepaid credit | D12: Lawyer | E12: No | F12: Not started | I12: A prepaid credit or voucher lives three years. Our terms give 60 days after a brand closes a programme. Whether section 63 reaches earned credits is the highest-value question in the list. | J12: docs/terms-brief.md
A13: 2.3 | B13: 2. Legal questions already written down | C13: POPIA section 57: prior authorisation for unique identifiers | D13: Lawyer | E13: No | F13: Not started | I13: Prior authorisation for linking unique identifiers across responsible parties. One phone number identifying one account across many brands is exactly the shape of the worked example, and authorisation has to come before the processing, not after. | J13: docs/terms-brief.md
A14: 2.4 | B14: 2. Legal questions already written down | C14: POPIA sections 18 and 72: the database is in the United States | D14: Lawyer | E14: No | F14: Not started | I14: The notice says nothing about it and probably has to. See also the Neon region item under Operations. | J14: docs/terms-brief.md
A15: 2.5 | B15: 2. Legal questions already written down | C15: Children: no minimum age means nothing stops a child joining | D15: Lawyer + Claude | E15: No | F15: Not started | I15: A brand that sets no minimum age is never asked one. A product fix, not a drafting one. | J15: docs/terms-brief.md
A16: 2.6 | B16: 2. Legal questions already written down | C16: Taking payment online | D16: Lawyer | E16: No | F16: Not started | I16: Only if self-serve signup happens: CPA on cancellation and refunds, ECTA on electronic transactions. | J16: docs/terms-brief.md
A17: 3.1 | B17: 3. Decisions only you can take | C17: Self-serve signup and payment | D17: Allan | E17: No | F17: Not started | I17: Under consideration. The subscription state machine already exists; what is missing is taking money and issuing the invite automatically. | J17: See the Self-serve signup tab
A18: 3.2 | B18: 3. Decisions only you can take | C18: The dormancy window | D18: Allan | E18: No | F18: Not started | H18: Do not set QUMO_DORMANT_ERASE_AFTER_DAYS without reading item 4 of docs/popia.md first. The sweep would erase unspent balances along with the dormant account. | I18: QUMO_DORMANT_ERASE_AFTER_DAYS is unset. POPIA section 14 and CPA sections 35 and 63 pull in opposite directions on it. | J18: docs/popia.md item 4
A19: 3.3 | B19: 3. Decisions only you can take | C19: Pick a slip reader, or decide not to yet | D19: Allan | E19: No | F19: Not started | H19: A cloud reader makes that vendor a POPIA operator and, if it is offshore, a section 72 transborder flow the shopper notice has to disclose. | I19: The photograph tier is built and disabled. docs/photo-capture.md has the four things to weigh. A reader running in our own process avoids the whole problem in the warning column. | J19: docs/photo-capture.md
A20: 3.4 | B20: 3. Decisions only you can take | C20: Brands whose door is the till | D20: Allan | E20: No | F20: Not started | I20: A coffee chain identifies a shopper at the point of sale and hands the reward over at the same counter. Qumo has no till door and no point of sale integration, and both sit behind items 4.1 and 4.2. Worth costing only if brands of that shape are a target. | J20: docs/seattle-coffee-review.md
A21: 3.5 | B21: 3. Decisions only you can take | C21: USSD, or not | D21: Allan | E21: No | F21: Not started | I21: The competitor sells it hard to feature-phone and data-off shoppers and we are simply absent from that market. A strategy question, not a backlog item. | J21: docs/competitive-position.md
A22: 3.6 | B22: 3. Decisions only you can take | C22: Language | D22: Allan | E22: No | F22: Not started | I22: English only today. Mass-market reach here is language-dependent.
A23: 4.1 | B23: 4. Product gaps | C23: A coupon cannot be redeemed | D23: Claude | E23: No | F23: Not started | H23: A brand honouring coupons by eye today has no defence against one code being used at every counter, every time. | I23: Separate from item 4.3 and worse. A completed stamp card issues a real coupon and nothing anywhere can mark it used: REDEEMED is in schema.prisma and in no TypeScript file. CouponFraudEvent.ALREADY_REDEEMED therefore can never fire, so the same screenshot works at every counter. | J23: docs/seattle-coffee-review.md
A24: 4.2 | B24: 4. Product gaps | C24: A stamp card cannot be earned from a till slip | D24: Claude | E24: No | F24: Not started | H24: At the award form's own default of 500 basis points, a R100 basket awards 500 stamps. | I24: The slip path resolves campaigns through one filter, PERCENT_OF_SPEND, so the only way to get stamps out of a slip is a share-of-spend rule in stamps, which multiplies stamps by rands. A flat-per-slip rule fixes it and removes the reason anyone would configure the broken combination. | J24: docs/seattle-coffee-review.md
A25: 4.3 | B25: 4. Product gaps | C25: Redemption | D25: Claude | E25: No | F25: Not started | I25: REDEMPTION_AVAILABLE is false. The largest unfinished edge, and CPA section 35 has views about it.
A26: 4.4 | B26: 4. Product gaps | C26: Correct-the-read | D26: Claude | E26: No | F26: Not started | I26: Proposed and not built: let a shopper fix a misread slip in the moment, identity fields only, never the amount. It is what makes photo capture defensible without storing anybody's photograph. | J26: docs/photo-capture.md
A27: 4.5 | B27: 4. Product gaps | C27: A reader implementation, once one is chosen | D27: Claude | E27: No | F27: Not started | I27: Plus the capture screen and published accuracy standards. Blocked on item 3.3. | J27: docs/photo-capture.md
A28: 4.6 | B28: 4. Product gaps | C28: Referral | D28: Claude | E28: No | F28: Not started | I28: Once there are shoppers to refer anybody.
A29: 4.7 | B29: 4. Product gaps | C29: WhatsApp | D29: Claude | E29: No | F29: Not started | I29: Planned, not built. Needs its own consent copy and version.
A30: 4.8 | B30: 4. Product gaps | C30: SMS re-consent has no path | D30: Claude | E30: No | F30: Not started | I30: A web shopper on an old consent version re-affirms at next sign-in. An SMS joiner has no next sign-in, so nobody who joined under sms-v1 will ever be shown sms-v2. Costs nothing while no aggregator is connected. | J30: lib/consumer/consent.ts
A31: 5.1 | B31: 5. Operations | C31: Tick DIRECT_DATABASE_URL for Preview in Vercel | D31: Allan | E31: No | F31: Not started | I31: Production has it. Until then every Preview build fails and that failure means nothing.
A32: 5.2 | B32: 5. Operations | C32: Twilio | D32: Allan | E32: No | F32: Not started | I32: Once approved and a real number is live, confirm an SMS actually arrives, then clear DEMO_LOGIN_PHONES and DEMO_LOGIN_CODE in production. In that order.
A33: 5.3 | B33: 5. Operations | C33: Vercel plan | D33: Allan | E33: No | F33: Not started | I33: Hobby is licensed for non-commercial personal use only and Vercel reads that broadly. | J33: docs/deploying.md
A34: 5.4 | B34: 5. Operations | C34: Neon region | D34: Allan | E34: No | F34: Not started | I34: The database is in us-east-2. Relevant to the POPIA section 72 question in item 2.4.
A35: 5.5 | B35: 5. Operations | C35: ERROR_WEBHOOK_URL is unset | D35: Allan | E35: No | F35: Not started | I35: Nothing is alerting anywhere.
A36: 5.6 | B36: 5. Operations | C36: Attach a reward to Copper Kettle's live Rounds card | D36: Allan | E36: No | F36: Not started | I36: It completes at 10 and names nothing, so shoppers would collect forever and be handed nothing.
A37: 6.1 | B37: 6. Brand and acquisition | C37: Brand guide | D37: Allan | E37: No | F37: In progress | I37: Context file written and handed over for the brand guide. | J37: docs/brand-context.md
A38: 6.2 | B38: 6. Brand and acquisition | C38: The acquisition site on qumo.co.za | D38: Allan | E38: No | F38: In progress | I38: Live and audited against the product. Copy corrections applied. | J38: docs/website-brief.md
A39: 6.3 | B39: 6. Brand and acquisition | C39: Domains | D39: Allan + Claude | E39: No | F39: Done | I39: Settled: site on qumo.co.za, product stays on qumo-app.com, the old apex redirects to the site. No migration, and standing the site up cannot affect anything running. | J39: docs/website-brief.md
A40: 6.4 | B40: 6. Brand and acquisition | C40: The call to action | D40: Allan + Claude | E40: No | F40: Waiting on someone | I40: Depends on the signup decision in item 3.1. Until then it is "request access".
A41: 7.1 | B41: 7. Housekeeping | C41: Delete ?ui=stacked and the stacked branch with it | D41: Claude | E41: No | F41: Not started | I41: Once the drawer has survived a real brand. Carrying two layouts is how one of them rots.
...

Sheet Summary
A1: Where things stand
A2: Every number here counts the Open items tab. Change a status there and these move.
A4: Section | B4: Not started | C4: In progress | D4: Waiting on someone | E4: Blocked | F4: Done | G4: Parked | H4: Items
A5: 1. Gates a pilot with real shoppers | B5: =COUNTIFS('Open items'!$B$5:$B$49,$A5,'Open items'!$F$5:$F$49,B$4) -> 6 | C5: =COUNTIFS('Open items'!$B$5:$B$49,$A5,'Open items'!$F$5:$F$49,C$4) -> 0 | D5: =COUNTIFS('Open items'!$B$5:$B$49,$A5,'Open items'!$F$5:$F$49,D$4) -> 0 | E5: =COUNTIFS('Open items'!$B$5:$B$49,$A5,'Open items'!$F$5:$F$49,E$4) -> 0 | F5: =COUNTIFS('Open items'!$B$5:$B$49,$A5,'Open items'!$F$5:$F$49,F$4) -> 0 | G5: =COUNTIFS('Open items'!$B$5:$B$49,$A5,'Open items'!$F$5:$F$49,G$4) -> 0 | H5: =SUM(B5:G5) -> 6
A6: 2. Legal questions already written down | B6: =COUNTIFS('Open items'!$B$5:$B$49,$A6,'Open items'!$F$5:$F$49,B$4) -> 6 | C6: =COUNTIFS('Open items'!$B$5:$B$49,$A6,'Open items'!$F$5:$F$49,C$4) -> 0 | D6: =COUNTIFS('Open items'!$B$5:$B$49,$A6,'Open items'!$F$5:$F$49,D$4) -> 0 | E6: =COUNTIFS('Open items'!$B$5:$B$49,$A6,'Open items'!$F$5:$F$49,E$4) -> 0 | F6: =COUNTIFS('Open items'!$B$5:$B$49,$A6,'Open items'!$F$5:$F$49,F$4) -> 0 | G6: =COUNTIFS('Open items'!$B$5:$B$49,$A6,'Open items'!$F$5:$F$49,G$4) -> 0 | H6: =SUM(B6:G6) -> 6
A7: 3. Decisions only you can take | B7: =COUNTIFS('Open items'!$B$5:$B$49,$A7,'Open items'!$F$5:$F$49,B$4) -> 6 | C7: =COUNTIFS('Open items'!$B$5:$B$49,$A7,'Open items'!$F$5:$F$49,C$4) -> 0 | D7: =COUNTIFS('Open items'!$B$5:$B$49,$A7,'Open items'!$F$5:$F$49,D$4) -> 0 | E7: =COUNTIFS('Open items'!$B$5:$B$49,$A7,'Open items'!$F$5:$F$49,E$4) -> 0 | F7: =COUNTIFS('Open items'!$B$5:$B$49,$A7,'Open items'!$F$5:$F$49,F$4) -> 0 | G7: =COUNTIFS('Open items'!$B$5:$B$49,$A7,'Open items'!$F$5:$F$49,G$4) -> 0 | H7: =SUM(B7:G7) -> 6
A8: 4. Product gaps | B8: =COUNTIFS('Open items'!$B$5:$B$49,$A8,'Open items'!$F$5:$F$49,B$4) -> 8 | C8: =COUNTIFS('Open items'!$B$5:$B$49,$A8,'Open items'!$F$5:$F$49,C$4) -> 0 | D8: =COUNTIFS('Open items'!$B$5:$B$49,$A8,'Open items'!$F$5:$F$49,D$4) -> 0 | E8: =COUNTIFS('Open items'!$B$5:$B$49,$A8,'Open items'!$F$5:$F$49,E$4) -> 0 | F8: =COUNTIFS('Open items'!$B$5:$B$49,$A8,'Open items'!$F$5:$F$49,F$4) -> 0 | G8: =COUNTIFS('Open items'!$B$5:$B$49,$A8,'Open items'!$F$5:$F$49,G$4) -> 0 | H8: =SUM(B8:G8) -> 8
A9: 5. Operations | B9: =COUNTIFS('Open items'!$B$5:$B$49,$A9,'Open items'!$F$5:$F$49,B$4) -> 6 | C9: =COUNTIFS('Open items'!$B$5:$B$49,$A9,'Open items'!$F$5:$F$49,C$4) -> 0 | D9: =COUNTIFS('Open items'!$B$5:$B$49,$A9,'Open items'!$F$5:$F$49,D$4) -> 0 | E9: =COUNTIFS('Open items'!$B$5:$B$49,$A9,'Open items'!$F$5:$F$49,E$4) -> 0 | F9: =COUNTIFS('Open items'!$B$5:$B$49,$A9,'Open items'!$F$5:$F$49,F$4) -> 0 | G9: =COUNTIFS('Open items'!$B$5:$B$49,$A9,'Open items'!$F$5:$F$49,G$4) -> 0 | H9: =SUM(B9:G9) -> 6
A10: 6. Brand and acquisition | B10: =COUNTIFS('Open items'!$B$5:$B$49,$A10,'Open items'!$F$5:$F$49,B$4) -> 0 | C10: =COUNTIFS('Open items'!$B$5:$B$49,$A10,'Open items'!$F$5:$F$49,C$4) -> 2 | D10: =COUNTIFS('Open items'!$B$5:$B$49,$A10,'Open items'!$F$5:$F$49,D$4) -> 1 | E10: =COUNTIFS('Open items'!$B$5:$B$49,$A10,'Open items'!$F$5:$F$49,E$4) -> 0 | F10: =COUNTIFS('Open items'!$B$5:$B$49,$A10,'Open items'!$F$5:$F$49,F$4) -> 1 | G10: =COUNTIFS('Open items'!$B$5:$B$49,$A10,'Open items'!$F$5:$F$49,G$4) -> 0 | H10: =SUM(B10:G10) -> 4
A11: 7. Housekeeping | B11: =COUNTIFS('Open items'!$B$5:$B$49,$A11,'Open items'!$F$5:$F$49,B$4) -> 6 | C11: =COUNTIFS('Open items'!$B$5:$B$49,$A11,'Open items'!$F$5:$F$49,C$4) -> 0 | D11: =COUNTIFS('Open items'!$B$5:$B$49,$A11,'Open items'!$F$5:$F$49,D$4) -> 0 | E11: =COUNTIFS('Open items'!$B$5:$B$49,$A11,'Open items'!$F$5:$F$49,E$4) -> 0 | F11: =COUNTIFS('Open items'!$B$5:$B$49,$A11,'Open items'!$F$5:$F$49,F$4) -> 0 | G11: =COUNTIFS('Open items'!$B$5:$B$49,$A11,'Open items'!$F$5:$F$49,G$4) -> 0 | H11: =SUM(B11:G11) -> 6
A12: 8. Parked | B12: =COUNTIFS('Open items'!$B$5:$B$49,$A12,'Open items'!$F$5:$F$49,B$4) -> 0 | C12: =COUNTIFS('Open items'!$B$5:$B$49,$A12,'Open items'!$F$5:$F$49,C$4) -> 0 | D12: =COUNTIFS('Open items'!$B$5:$B$49,$A12,'Open items'!$F$5:$F$49,D$4) -> 0 | E12: =COUNTIFS('Open items'!$B$5:$B$49,$A12,'Open items'!$F$5:$F$49,E$4) -> 0 | F12: =COUNTIFS('Open items'!$B$5:$B$49,$A12,'Open items'!$F$5:$F$49,F$4) -> 0 | G12: =COUNTIFS('Open items'!$B$5:$B$49,$A12,'Open items'!$F$5:$F$49,G$4) -> 3 | H12: =SUM(B12:G12) -> 3
A13: All sections | B13: =SUM(B5:B12) -> 38 | C13: =SUM(C5:C12) -> 2 | D13: =SUM(D5:D12) -> 1 | E13: =SUM(E5:E12) -> 0 | F13: =SUM(F5:F12) -> 1 | G13: =SUM(G5:G12) -> 3 | H13: =SUM(H5:H12) -> 45
A16: Still open, by owner
A17: Owner | B17: Not done | C17: Of those, gates a pilot
A18: Allan | B18: =COUNTIFS('Open items'!$D$5:$D$49,$A18,'Open items'!$F$5:$F$49,"<>Done",'Open items'!$F$5:$F$49,"<>Parked") -> 15 | C18: =COUNTIFS('Open items'!$D$5:$D$49,$A18,'Open items'!$F$5:$F$49,"<>Done",'Open items'!$F$5:$F$49,"<>Parked",'Open items'!$E$5:$E$49,"Yes") -> 1
A19: Lawyer | B19: =COUNTIFS('Open items'!$D$5:$D$49,$A19,'Open items'!$F$5:$F$49,"<>Done",'Open items'!$F$5:$F$49,"<>Parked") -> 8 | C19: =COUNTIFS('Open items'!$D$5:$D$49,$A19,'Open items'!$F$5:$F$49,"<>Done",'Open items'!$F$5:$F$49,"<>Parked",'Open items'!$E$5:$E$49,"Yes") -> 3
A20: Claude | B20: =COUNTIFS('Open items'!$D$5:$D$49,$A20,'Open items'!$F$5:$F$49,"<>Done",'Open items'!$F$5:$F$49,"<>Parked") -> 15 | C20: =COUNTIFS('Open items'!$D$5:$D$49,$A20,'Open items'!$F$5:$F$49,"<>Done",'Open items'!$F$5:$F$49,"<>Parked",'Open items'!$E$5:$E$49,"Yes") -> 1
A21: Allan + lawyer | B21: =COUNTIFS('Open items'!$D$5:$D$49,$A21,'Open items'!$F$5:$F$49,"<>Done",'Open items'!$F$5:$F$49,"<>Parked") -> 1 | C21: =COUNTIFS('Open items'!$D$5:$D$49,$A21,'Open items'!$F$5:$F$49,"<>Done",'Open items'!$F$5:$F$49,"<>Parked",'Open items'!$E$5:$E$49,"Yes") -> 1
A22: Lawyer + Claude | B22: =COUNTIFS('Open items'!$D$5:$D$49,$A22,'Open items'!$F$5:$F$49,"<>Done",'Open items'!$F$5:$F$49,"<>Parked") -> 1 | C22: =COUNTIFS('Open items'!$D$5:$D$49,$A22,'Open items'!$F$5:$F$49,"<>Done",'Open items'!$F$5:$F$49,"<>Parked",'Open items'!$E$5:$E$49,"Yes") -> 0
A23: Allan + Claude | B23: =COUNTIFS('Open items'!$D$5:$D$49,$A23,'Open items'!$F$5:$F$49,"<>Done",'Open items'!$F$5:$F$49,"<>Parked") -> 1 | C23: =COUNTIFS('Open items'!$D$5:$D$49,$A23,'Open items'!$F$5:$F$49,"<>Done",'Open items'!$F$5:$F$49,"<>Parked",'Open items'!$E$5:$E$49,"Yes") -> 0
A26: Gates a pilot and not yet done | B26: =COUNTIFS('Open items'!$E$5:$E$49,"Yes",'Open items'!$F$5:$F$49,"<>Done") -> 6
A27: Nothing under section 1 is optional before a real shopper signs up.

Sheet Self-serve signup
A1: On self-serve signup, since it is being weighed
A2: Three pieces of very different size. It is less "build self-service signup" than "replace the human gate with a payment gate", and what is on the other side stays an invite.
A4: Piece | B4: State | C4: What it is
A5: 1. Subscription state | B5: Done | C5: Per-brand TRIALING / ACTIVE / CANCELLED / CLOSED, cancel, resume, period end, and a nightly job that closes elapsed programmes. Already load-bearing: it decides whether scans earn, and the 60-day honour window hangs off it.
A6: 2. Taking money | B6: Nothing exists | C6: No provider wired at all. A provider, a webhook, a return URL.
A7: 3. Issuing the invite | B7: Partly there | C7: The provision route and setup key are already an invite mechanism. What is missing is generating a one-time link rather than handing a key over by hand.
